<?xml version="1.0" ?>
 
<robot name="my_robot" xmlns:xacro="http://www.ros.org/wiki/xacro">
    <link name="base_link">
        <visual>
            <origin rpy="0 0 0" xyz="0 0 0.05"/>
            <geometry>
                <box size="2 3 0.1"/>
            </geometry>
        </visual>
    </link>
    
    <joint name="base_link_link_1" type="revolute">
        <axis xyz="0 0 1" />
        <limit effort="1000.0" lower="-3.14" upper="3.14" velocity="0.5" />
        <origin rpy="0 0 0" xyz="0 0 0.1"/>
        <parent link="base_link"/>
        <child link="link1"/>
    </joint>
    
    <link name="link1">
        <visual>
            <origin rpy="0 0 0" xyz="0 0 0.2"/>
            <geometry>
                <cylinder radius="0.5" length="0.4"/>
            </geometry>
        </visual>
    </link>

    <joint name="my_first_link1_link_2" type="revolute">
        <axis xyz="0 1 0" />
        <limit effort="1000.0" lower="-1" upper="1" velocity="0.5" />
        <origin rpy="0 0 0" xyz="0 0 0.4"/>
        <parent link="link1"/>
        <child link="link2"/>
    </joint>

    <link name="link2">
        <visual>
            <origin rpy="0 0 0" xyz="0 0 0.65"/>
            <geometry>
                <box size="0.2 0.2 1.3"/>
            </geometry>
        </visual>
    </link>

    <joint name="link2_link_3" type="revolute">
        <axis xyz="1 0 0" />
        <limit effort="1000.0" lower="0" upper="1" velocity="0.5" />
        <origin rpy="0 0 0" xyz="0 0 1.3"/>
        <parent link="link2"/>
        <child link="link3"/>
    </joint>

    <link name="link3">
        <visual>
            <origin rpy="0 0 0" xyz="0 0 0.4"/>
            <geometry>
                <cylinder radius="0.1" length="0.8"/>
            </geometry>
        </visual>
    </link>


    <joint name="link3_link_4" type="revolute">
        <axis xyz="0 1 0" />
        <limit effort="1000.0" lower="0" upper="1" velocity="0.5" />
        <origin rpy="0 0 0" xyz="0 0 0.8"/>
        <parent link="link3"/>
        <child link="link4"/>
    </joint>

    <link name="link4">
        <visual>
            <origin rpy="0 0 0" xyz="0 0 0.25"/>
            <geometry>
                <cylinder radius="0.05" length="0.5"/>
            </geometry>
        </visual>
    </link>

    <joint name="link4_link_5" type="fixed">
        <axis xyz="1 0 0" />
        <limit effort="1000.0" lower="0" upper="1" velocity="0.5" />
        <origin rpy="0.75 0 0" xyz="0 0 0.48"/>
        <parent link="link4"/>
        <child link="link5"/>
    </joint>

    <link name="link5">
        <visual>
            <origin rpy="0 0 0" xyz="0 0.1 0"/>
            <geometry>
                <box size="0.01 0.2 0.05"/>
            </geometry>
        </visual>
    </link>
    
    <joint name="link5_link_6" type="fixed">
        <axis xyz="1 0 0" />
        <limit effort="1000.0" lower="0" upper="1" velocity="0.5" />
        <origin rpy="-0.75 0 0" xyz="0 0.149 -0.01"/>
        <parent link="link5"/>
        <child link="link6"/>
    </joint>

    <link name="link6">
        <visual>
            <origin rpy="0 0 0" xyz="0 0 0.1"/>
            <geometry>
                <box size="0.01 0.05 0.2"/>
            </geometry>
        </visual>
    </link>

    <joint name="link4_link_7" type="fixed">
        <axis xyz="1 0 0" />
        <limit effort="1000.0" lower="0" upper="1" velocity="0.5" />
        <origin rpy="0.75 0 2.09" xyz="0 0 0.48"/>
        <parent link="link4"/>
        <child link="link7"/>
    </joint>

    <link name="link7">
        <visual>
            <origin rpy="0 0 0" xyz="0 0.1 0"/>
            <geometry>
                <box size="0.01 0.2 0.05"/>
            </geometry>
        </visual>
    </link>

    <joint name="link7_link_8" type="fixed">
        <axis xyz="1 0 0" />
        <limit effort="1000.0" lower="0" upper="1" velocity="0.5" />
        <origin rpy="-0.75 0 0" xyz="0 0.149 -0.01"/>
        <parent link="link7"/>
        <child link="link8"/>
    </joint>

    <link name="link8">
        <visual>
            <origin rpy="0 0 0" xyz="0 0 0.1"/>
            <geometry>
                <box size="0.01 0.05 0.2"/>
            </geometry>
        </visual>
    </link>

	<joint name="link4_link_9" type="fixed">
        <axis xyz="1 0 0" />
        <limit effort="1000.0" lower="0" upper="1" velocity="0.5" />
        <origin rpy="0.75 0 -2.09" xyz="0 0 0.48"/>
        <parent link="link4"/>
        <child link="link9"/>
    </joint>

    <link name="link9">
        <visual>
            <origin rpy="0 0 0" xyz="0 0.1 0"/>
            <geometry>
                <box size="0.01 0.2 0.05"/>
            </geometry>
        </visual>
    </link>

    <joint name="link9_link_10" type="fixed">
        <axis xyz="1 0 0" />
        <limit effort="1000.0" lower="0" upper="1" velocity="0.5" />
        <origin rpy="-0.75 0 0" xyz="0 0.149 -0.01"/>
        <parent link="link9"/>
        <child link="link10"/>
    </joint>

    <link name="link10">
        <visual>
            <origin rpy="0 0 0" xyz="0 0 0.1"/>
            <geometry>
                <box size="0.01 0.05 0.2"/>
            </geometry>
        </visual>
    </link>

</robot>
